<?xml version="1.0"?>
<sdf version='1.6'>
  <world name='default'>


    <light type="directional" name="sun">
      <cast_shadows>true</cast_shadows>
      <pose>0 0 10 0 0 0</pose>
      <diffuse>1 1 1 1</diffuse>
      <specular>0.5 0.5 0.5 1</specular>
      <attenuation>
        <range>1000</range>
        <constant>0.9</constant>
        <linear>0.01</linear>
        <quadratic>0.001</quadratic>
      </attenuation>
      <direction>-0.5 0.1 -0.9</direction>
    </light>

    <light name='user_directional_light_0' type='directional'>
      <pose>0 0 1 0 0 0</pose>
    </light>
    
    <model name='unit_box'>
    <static>true</static>
      <pose>25 32 43 0 0 0</pose>
      <link name='link'>
        <visual name='visual'>
          <geometry>
            <box>
              <size>1 1 1</size>
            </box>
          </geometry>
        </visual>
        <collision name="box_col">
          <geometry>
            <box>
              <size>1 1 1</size>
            </box>
          </geometry>
        </collision>
      </link>
    </model>


    <model name="ground">
       <static>true</static>

      <link name="ground_link">
        <visual name="ground">
          <geometry>
            <box>
              <size>100 100 0.1</size>
            </box>
          </geometry>
          <material>
      <ambient>1 1 1 1</ambient>   <!-- White ambient light -->
      <diffuse>1 1 1 1</diffuse>   <!-- White diffuse color -->
      <specular>0.1 0.1 0.1 1</specular> <!-- Slight shininess -->
      <emissive>0 0 0 1</emissive> <!-- No glow -->
    </material>
        </visual>
        <collision name="ground_col">
          <geometry>
            <box>
              <size>100 100 0.1</size>
            </box>
          </geometry>
        </collision>
      </link>
      </model>


    <model name="mecanum_car">
   <!-- <static>true</static> -->
        <link name="chassis">
        <pose>0 0 1.8 0 0 0</pose>
            <inertial>
            <inertia>
                <ixx>2.501</ixx>
                <ixy>0</ixy>
                <ixz>0</ixz>
                <iyy>2.501</iyy>
                <iyz>0</iyz>
                <izz>5</izz>
            </inertia>
            <mass>42.0</mass>
            </inertial>
            <visual name='visual'>
            <geometry>
            <mesh>
                <uri>model://Mainframe_1.stl</uri> <scale> 0.01 0.01 0.01</scale>
            </mesh>
            </geometry>
                <material>
                    <ambient>0.1 0.1 0.1 1</ambient>
                    <diffuse>0.1 0.1 0.2 1</diffuse>
                    <specular>0 0 0 0</specular>
                    <emissive>0 0 0 1</emissive>
            </material>
            </visual>
            <collision name="camera_col">
            <geometry>
                <box>
                <size>1 1 1</size>
                </box>
            </geometry>
            </collision>

        <sensor name="imu_sensor" type="imu">
            <always_on>1</always_on>
            <update_rate>1</update_rate>
            <visualize>true</visualize>
            <topic>imu</topic>
        </sensor>
        </link>

        <link name="dolly">
            <static>true</static>
            <pose>0 0 2.45 0 0 0</pose>
             <visual name='visual'>
            <geometry>
            <mesh>
                <uri>model://dolly_1.stl</uri> <scale> 0.01 0.01 0.01</scale>
            </mesh>
            </geometry>
                <material>
                <ambient>0.2 0.8 0.2 1</ambient>
                <diffuse>0.8 0 0 1</diffuse>
            </material>
            </visual>
            <collision name="dolly_col">
            <geometry>
                <box>
                <size>1 1 1</size>
                </box>
            </geometry>
            </collision>
            
        </link>

        <link name="left_front">
            <pose>1.72 3.1 1.3 0 0 1.5707</pose>
            <inertial>
            <inertia>
                <ixx>2.501</ixx>
                <ixy>0</ixy>
                <ixz>0</ixz>
                <iyy>2.501</iyy>
                <iyz>0</iyz>
                <izz>5</izz>
            </inertia>
            <mass>120.0</mass>
            </inertial>
            <visual name='visual'>
            <geometry>
            <mesh>
                <uri>model://wheel_1.stl</uri> <scale> 0.01 0.01 0.01</scale>
            </mesh>
            </geometry>
                <material>
                <ambient>0.2 0.8 0.2 1</ambient>
                <diffuse>0.8 0 0 1</diffuse>
            </material>
            </visual>
            <collision name="camera_col">
            <geometry>
            <cylinder>
                <radius>0.5</radius>
                <length>1</length>
            </cylinder>
            </geometry>
            </collision>
        </link>

        <link name="right_front">
            <pose>1.72 -3.1 1.3 0 0 1.5707</pose>
            <inertial>
            <inertia>
                <ixx>2.501</ixx>
                <ixy>0</ixy>
                <ixz>0</ixz>
                <iyy>2.501</iyy>
                <iyz>0</iyz>
                <izz>5</izz>
            </inertia>
            <mass>120.0</mass>
            </inertial>
            <visual name='visual'>
            <geometry>
            <mesh>
                <uri>model://wheel_2.stl</uri> <scale> 0.01 0.01 0.01</scale>
            </mesh>
            </geometry>
                <material>
                <ambient>0.2 0.8 0.2 1</ambient>
                <diffuse>0.8 0 0 1</diffuse>
            </material>
            </visual>
            <collision name="camera_col">
            <geometry>
            <cylinder>
                <radius>0.5</radius>
                <length>1</length>
            </cylinder>
            </geometry>
            </collision>
            
        </link>

        <link name="left_rear">
            <pose>-1.72 3.1 1.3 0 0 1.5707</pose>
            <inertial>
            <inertia>
                <ixx>2.501</ixx>
                <ixy>0</ixy>
                <ixz>0</ixz>
                <iyy>2.501</iyy>
                <iyz>0</iyz>
                <izz>5</izz>
            </inertia>
            <mass>120.0</mass>
            </inertial>
            <visual name='visual'>
            <geometry>
            <mesh>
                <uri>model://wheel_2.stl</uri> <scale> 0.01 0.01 0.01</scale>
            </mesh>
            </geometry>
                <material>
                <ambient>0.2 0.8 0.2 1</ambient>
                <diffuse>0.8 0 0 1</diffuse>
            </material>
            </visual>
            <collision name="camera_col">
            <geometry>
            <cylinder>
                <radius>0.5</radius>
                <length>1</length>
            </cylinder>
            </geometry>
            </collision>

        </link>

        <link name="right_rear">
        <pose>-1.72 -3.1 1.3 0 0 1.5707</pose>
            <visual name='visual'>
            <inertial>
            <inertia>
                <ixx>2.501</ixx>
                <ixy>0</ixy>
                <ixz>0</ixz>
                <iyy>2.501</iyy>
                <iyz>0</iyz>
                <izz>5</izz>
            </inertia>
            <mass>120.0</mass>
            </inertial>
            <geometry>
            <mesh>
                <uri>model://wheel_1.stl</uri> <scale> 0.01 0.01 0.01</scale>
            </mesh>
            </geometry>
                <material>
                <ambient>0.2 0.8 0.2 1</ambient>
                <diffuse>0.8 0 0 1</diffuse>
            </material>
            </visual>
            <collision name="camera_col">
            <geometry>
            <cylinder>
                <radius>0.5</radius>
                <length>1</length>
            </cylinder>
            </geometry>
            </collision>

        </link>

    <joint name="dolly_joint" type="revolute">
        <parent>chassis</parent>
        <child>dolly</child>
        <axis>
          <xyz>0 1 0</xyz>
        </axis>
    </joint>

    <joint name="front_left_joint" type="revolute">
        <parent>chassis</parent>
        <child>left_front</child>
        <axis>
          <xyz>1 0 0</xyz>
        </axis>
    </joint>

    <joint name="front_right_joint" type="revolute">
        <parent>chassis</parent>
        <child>right_front</child>
        <axis>
          <xyz>1 0 0</xyz>
        </axis>
    </joint>

        <joint name="rear_left_joint" type="revolute">
        <parent>chassis</parent>
        <child>left_rear</child>
        <axis>
          <xyz>1 0 0</xyz>
        </axis>
    </joint>

        <joint name="rear_right_joint" type="revolute">
        <parent>chassis</parent>
        <child>right_rear</child>
        <axis>
          <xyz>1 0 0</xyz>
        </axis>
    </joint>

    <plugin
    filename="gz-sim-joint-position-controller-system"
    name="gz::sim::systems::JointPositionController">
    <joint_name>dolly_joint</joint_name>
    <topic>/dolly</topic>
    <p_gain>1</p_gain>
    <i_gain>0.01</i_gain>
    <d_gain>0.7</d_gain>
    <i_max>1</i_max>
    <i_min>-1</i_min>
    <cmd_max>1000</cmd_max>
    <cmd_min>-1000</cmd_min>
    </plugin>
    <plugin
    filename="gz-sim-pose-publisher-system"
    name="gz::sim::systems::PosePublisher">
    <publish_link_pose>true</publish_link_pose>
    <publish_visual_pose>true</publish_visual_pose>
    <publish_model_pose>true</publish_model_pose>
    <use_pose_vector_msg>true</use_pose_vector_msg>
    <static_publisher>true</static_publisher>
    <static_update_frequency>1</static_update_frequency>
    </plugin>


<plugin name="ignition::gazebo::systems::JointStatePublisher"
        filename="libignition-gazebo-joint-state-publisher-system.so">
        <joint_name>front_left_joint</joint_name>
        <topic>/lf_wheel</topic>
</plugin>
<plugin name="ignition::gazebo::systems::JointStatePublisher"
        filename="libignition-gazebo-joint-state-publisher-system.so">
        <joint_name>front_right_joint</joint_name>
        <topic>rf_wheel</topic>
</plugin>

<plugin name="ignition::gazebo::systems::JointStatePublisher"
        filename="libignition-gazebo-joint-state-publisher-system.so">
        <joint_name>rear_left_joint</joint_name>
        <topic>lr_wheel</topic>
</plugin>

<plugin name="ignition::gazebo::systems::JointStatePublisher"
        filename="libignition-gazebo-joint-state-publisher-system.so">
        <joint_name>rear_right_joint</joint_name>
        <topic>rr_wheel</topic>

</plugin>
    <plugin
    filename="gz-sim-odometry-publisher-system"
    name="gz::sim::systems::OdometryPublisher">
    <odom_frame>diff_drive/odom</odom_frame>
    <robot_base_frame>chassis</robot_base_frame>
    </plugin>


    <plugin
    filename="gz-sim-joint-controller-system"
    name="gz::sim::systems::JointController">
    <joint_name>front_left_joint</joint_name>
    <initial_velocity>0.0</initial_velocity>
    <topic>wheel_vel/left_front</topic>
    </plugin>

    <plugin
    filename="gz-sim-joint-controller-system"
    name="gz::sim::systems::JointController">
    <joint_name>front_right_joint</joint_name>
    <initial_velocity>0.0</initial_velocity>
    <topic>wheel_vel/right_front</topic>
    </plugin>

    <plugin
    filename="gz-sim-joint-controller-system"
    name="gz::sim::systems::JointController">
    <joint_name>rear_left_joint</joint_name>
    <initial_velocity>0.0</initial_velocity>
    <topic>wheel_vel/left_rear</topic>
    </plugin>

    <plugin
    filename="gz-sim-joint-controller-system"
    name="gz::sim::systems::JointController">
    <joint_name>rear_right_joint</joint_name>
    <initial_velocity>0.0</initial_velocity>
    <topic>wheel_vel/right_rear</topic>
    </plugin>


    <plugin filename="libignition-gazebo-imu-system.so"
        name="ignition::gazebo::systems::Imu">
    </plugin>
     <plugin
      filename="gz-sim-user-commands-system"
      name="gz::sim::systems::UserCommands">
    </plugin>
    <plugin
      filename="gz-sim-scene-broadcaster-system"
      name="gz::sim::systems::SceneBroadcaster">
    </plugin>
    <plugin
      filename="gz-sim-sensors-system"
      name="gz::sim::systems::Sensors">
      <render_engine>ogre2</render_engine>
    </plugin>
    <plugin
      filename="gz-sim-contact-system"
      name="gz::sim::systems::Contact">
    </plugin>



    </model>


  </world>
</sdf>

